Workbook

Sheet Summary
A1: VERDICT SUMMARY (auto-computed from the sheets above)
A3: Bed: 1700 x 1700 mm (customer) | Torch: Hypertherm 45 | Z feed: 2000 N (customer) | 15 m/min plasma
A5: Constraint | B5: Demand | C5: Available | D5: Margin | E5: PASS? | F5: Note
A6: X/Y feed force (worst slot) | B6: 135 N avg (~2-3x peak) | C6: >= 200 N (both drives) | D6: >=1.5x | E6: PASS | F6: see XY-Force + Drive-XY
A7: X/Y speed 15 m/min (plasma) | B7: 15000 mm/min | C7: ballscrew >=16-20mm lead OR rack | D7: ok | E7: PASS | F7: encoder caps at 900 rpm -> needs lead>=~17mm
A8: X/Y cut torque @ 150 N | B8: 0.5-2.1 Nm | C8: 4.0 Nm | D8: 1.9-8x | E8: PASS | F8: at low rpm = full torque
A9: Ballscrew critical speed (2500 mm span) | B9: 750 rpm (20 mm lead @ 15 m/min) | C9: =ROUND(Inputs!$B$53*Inputs!$B$54*10000000/(Inputs!$B$4+Inputs!$B$22)^2,0) rpm | D9: FAIL vs 50% rule | E9: MARGINAL | F9: use 25mm dia screw or mid-support for 20mm lead @15m/min
A10: Z feed force | B10: 2000 N | C10: 4523 N (2.5mm lead, 4Nm) | D10: 2.3x | E10: PASS | F10: self-locking holds position
A11: Z thrust bearing | B11: 2000 N axial | C11: 96400 N (51217) | D11: 48x | E11: PASS | F11: the lathe-type bearing
A12: Z rails | B12: 2000 N | C12: 73360 N (2x HGH20) | D12: 37x | E12: PASS
A13: Drill torque 6mm steel | B13: 2 Nm | C13: ~4 Nm (Flipsky cont) | D13: 2x | E13: PASS | F13: off-axis + belt
A15: BOTTOM LINE
A16: BOTTOM LINE — corrected for the customer's REAL longest axis (2500 mm, from the ODS): at that span a ballscrew's critical speed is the BINDING constraint for 15 m/min plasma — every ballscrew lead needs >750 rpm, which exceeds even 100% of critical speed (K=15.1, D=25, L=2800 -> ~480 rpm). The RACK has no critical-speed limit, so for the LONG axis the rack is the safer 15 m/min choice; a ballscrew works only if you go larger-diameter, add a mid-span bearing, or accept slower rapids. Force and torque still pass easily everywhere (2000 N is Z-only). Edit K and D (yellow) to test your actual screw.
A21: WATER TABLE + TABLE HEIGHT LIFT
A22: Water load (1700x1700x100 mm) | B22: ≈ 290 kg / 2845 N | C22: + ~250 kg structure = ~540 kg full (see Water-Table sheet)
A23: Counterweight max (passive safety) | B23: ≤ 0.9 x EMPTY weight | C23: guarantees a drained table can't self-lift into the plasma head
A24: Manual effort (full, 4:1 MA) | B24: ≈ 80 kg equiv | C24: (full − CW)/4 — one person workable
A25: Cable / pins safety factor | B25: ≥ 10 / ≥ 5 | C25: 6 mm steel cable, 2x M12 pins at set positions
A26: Fill / drain | B26: ≈ 6 min / gravity | C26: 50 L/min basic pump; sump drain
A28: SAFETY NOTE — empty-water crash mode:
A29: If the counterweight exceeded the EMPTY table weight, a drained table would self-lift and slam into the plasma head. Passive fix: CW < 0.9 x empty weight. Pins then hold every set position with the cable slacked — no power or brake needed at rest.

Sheet Inputs
A1: CONSTRAINTS — INPUTS (edit the YELLOW cells; every sheet recomputes)
A3: CUSTOMER SPEC (from customer / guild)
A4: Longest travel axis (screw span basis) | B4: 2500 | C4: mm | D4: customer: bedsize 1700x1700mm
A5: Min sheet to cut (customer) | B5: 1000 x 2000 | C5: mm | D5: customer
A6: Torch | B6: Hypertherm POWERMAX 65 (customer supplies, w/ CPC) | C6: - | D6: customer
A7: Z drilling feed force | B7: 2000 | C7: N | D7: customer — downward drilling force (NOT an X/Y load)
A8: Max hole diameter | B8: 6 | C8: mm | D8: customer — into steel
A9: Use case | B9: plasma+THC 15 m/min; light engrave/emboss/mill/drill (slow) | C9: - | D9: customer
A10: MATERIAL / CUTTING (assumptions — adjust to your shop experience)
A11: Kc mild steel | B11: 2500 | C11: N/mm2 | D11: Sumitomo: general steel 2500-3000
A12: Kc brass | B12: 1500 | C12: N/mm2 | D12: brass band 1000-1500
A13: Feed / tangential ratio | B13: 0.4 | C13: - | D13: rake-angle dependent, 0.3-0.5 for steel
A14: Depth of cut ap (default) | B14: 3 | C14: mm | D14: customer: 3 mm depth of cut
A15: Feed per tooth fz (default) | B15: 0.05 | C15: mm/tooth | D15: light milling 2-flute; engraving ~0.03
A16: Engagement (default) | B16: 0.7 | C16: - | D16: profile 0.5-0.7; slotting 0.9
A17: MOTOR / DRIVE (24HS40-5004D NEMA 24 closed-loop)
A18: Rated torque | B18: 4 | C18: Nm | D18: holding torque, datasheet
A19: Encoder max rpm | B19: 900 | C19: rpm | D19: 60 kHz / 4000 CPR — this caps feed speed
A20: Ballscrew efficiency | B20: 0.9 | C20: - | D20: typical ballscrew
A21: Rack efficiency | B21: 0.95 | C21: - | D21: rack & pinion
A22: Screw end margin (both ends) | B22: 300 | C22: mm | D22: nut + bearing overhang beyond stroke
A23: Torque fraction usable at speed | B23: 0.4 | C23: - | D23: conservative: 40% of rated at ~200-900 rpm
A24: GUIDES (Hiwin HGH20CA)
A25: HGH20 static rating / block | B25: 36680 | C25: N | D25: Co per block, Hiwin HG catalog
A26: Blocks per axis | B26: 2 | C26: - | D26: 2 rails x 2 blocks
A27: SPEED TARGETS
A28: Plasma speed | B28: 15 | C28: m/min | D28: customer rapid / thin-steel
A29: Cut speed | B29: 5 | C29: m/min | D29: 3 mm steel typical
A31: CUSTOMER REQUIREMENTS (Plasma Table Constraints.ods, 2026-10-21)
A32: Outer maximum dimensions (X, Y) | B32: 1600 x 2500 | C32: mm | D32: customer 'outer max'
A33: Min sheet to cut | B33: 1000 x 2000 | C33: mm | D33: 'able to cut at least 1000x2000 sheets'
A34: Available (customer) | B34: 1700 | C34: mm | D34: customer '1700mm'
A35: Torch (customer buys) | B35: Powermax 65 + CPC
A36: Control software | B36: LinuxCNC Qtplasmac + SheetCAM (local at machine)
A37: Motion controller | B37: Mesa 7i76e (Ethernet FPGA)
A38: THC — touch-off | B38: Mesa THCAD-5 (ohmic sensing)
A39: THC — real-time | B39: Mesa THCAD-10 (voltage sensing)
A40: EMI/EMI concern | B40: high — plasma cutter generates lots of electrical noise
A42: DESIRED FEATURES (customer)
A43: Plasma cutting with THC + water table
...

Sheet XY-Force
A1: X/Y FEED FORCE DEMAND Ff = ratio x Kc x fz x ap x e
A2: Change a case's fz/ap/e to test your real job. Ff is what the X/Y drive must push (AVERAGE).
A4: Case | B4: d (mm) | C4: ap (mm) | D4: fz (mm/t) | E4: e (eng) | F4: A = fz.ap.e (mm2) | G4: Ft = Kc.A (N) | H4: Ff = 0.4.Ft (N)
A5: Engraving (3 mm tool) | B5: 3 | C5: 1 | D5: 0.03 | E5: 0.7 | F5: =D5*C5*E5 | G5: =Inputs!$B$11*F5 | H5: =Inputs!$B$13*G5
A6: Light mill (6 mm 2-fl) | B6: 6 | C6: 3 | D6: 0.05 | E6: 0.7 | F6: =D6*C6*E6 | G6: =Inputs!$B$11*F6 | H6: =Inputs!$B$13*G6
A7: Slotting (10 mm 2-fl) | B7: 10 | C7: 3 | D7: 0.05 | E7: 0.9 | F7: =D7*C7*E7 | G7: =Inputs!$B$11*F7 | H7: =Inputs!$B$13*G7
A8: Brass gear (6 mm 2-fl) | B8: 6 | C8: 3 | D8: 0.05 | E8: 0.7 | F8: =D8*C8*E8 | G8: =Inputs!$B$12*F8 | H8: =Inputs!$B$13*G8
A9: X/Y FORCE ENVELOPE (min-max of Ff) | H9: =MIN(H5:H8)&" .. "&MAX(H5:H8)&" N"
A11: These are AVERAGE feed forces. Instantaneous peaks are ~2-3x higher but last milliseconds; the Drive sheet checks capability with >=1.5x margin so peaks are covered.

Sheet Drive-XY
A1: X/Y DRIVE CAPABILITY vs DEMAND (plasma corner AND cutting corner must both pass)
A2: Plasma corner = 15 m/min @ ~35 N (nearly unloaded). Cutting corner = 150 N @ low speed (full torque).
A4: Drive | B4: Lead / mod | C4: Teeth | D4: rpm for 15 m/min | E4: Speed @ rpm (mm/min) | F4: Force avail @15m/min (N) | G4: Torque for 150 N cut (Nm) | H4: % of 4 Nm motor | I4: Screw len (mm) | J4: Critical speed (rpm) | K4: 50% crit (rpm) | L4: <900rpm? | M4: VERDICT
A5: Ballscrew 5 mm lead | B5: 5 | C5: - | D5: =ROUND(15000/B5,0) | E5: =B5*D5 | F5: =ROUND(2*3.14159*Inputs!$B$20*(Inputs!$B$18*Inputs!$B$23)*1000/B5,0) | G5: =ROUND(150*B5/(2*3.14159*Inputs!$B$20*1000),2) | H5: =ROUND(G5/Inputs!$B$18*100,0) | I5: =(Inputs!$B$4+Inputs!$B$22) | J5: =ROUND(Inputs!$B$53*Inputs!$B$54*10000000/I5^2,0) | K5: =J5/2 | L5: =IF(D5<=Inputs!$B$19,"yes","NO") | M5: =IF(AND(F5>=35,H5<=100,D5<=Inputs!$B$19,D5<=K5),"PASS","FAIL")
A6: Ballscrew 10 mm lead | B6: 10 | C6: - | D6: =ROUND(15000/B6,0) | E6: =B6*D6 | F6: =ROUND(2*3.14159*Inputs!$B$20*(Inputs!$B$18*Inputs!$B$23)*1000/B6,0) | G6: =ROUND(150*B6/(2*3.14159*Inputs!$B$20*1000),2) | H6: =ROUND(G6/Inputs!$B$18*100,0) | I6: =(Inputs!$B$4+Inputs!$B$22) | J6: =ROUND(Inputs!$B$53*Inputs!$B$54*10000000/I6^2,0) | K6: =J6/2 | L6: =IF(D6<=Inputs!$B$19,"yes","NO") | M6: =IF(AND(F6>=35,H6<=100,D6<=Inputs!$B$19,D6<=K6),"PASS","FAIL")
A7: Ballscrew 16 mm lead | B7: 16 | C7: - | D7: =ROUND(15000/B7,0) | E7: =B7*D7 | F7: =ROUND(2*3.14159*Inputs!$B$20*(Inputs!$B$18*Inputs!$B$23)*1000/B7,0) | G7: =ROUND(150*B7/(2*3.14159*Inputs!$B$20*1000),2) | H7: =ROUND(G7/Inputs!$B$18*100,0) | I7: =(Inputs!$B$4+Inputs!$B$22) | J7: =ROUND(Inputs!$B$53*Inputs!$B$54*10000000/I7^2,0) | K7: =J7/2 | L7: =IF(D7<=Inputs!$B$19,"yes","NO") | M7: =IF(AND(F7>=35,H7<=100,D7<=Inputs!$B$19,D7<=K7),"PASS","FAIL")
A8: Ballscrew 20 mm lead | B8: 20 | C8: - | D8: =ROUND(15000/B8,0) | E8: =B8*D8 | F8: =ROUND(2*3.14159*Inputs!$B$20*(Inputs!$B$18*Inputs!$B$23)*1000/B8,0) | G8: =ROUND(150*B8/(2*3.14159*Inputs!$B$20*1000),2) | H8: =ROUND(G8/Inputs!$B$18*100,0) | I8: =(Inputs!$B$4+Inputs!$B$22) | J8: =ROUND(Inputs!$B$53*Inputs!$B$54*10000000/I8^2,0) | K8: =J8/2 | L8: =IF(D8<=Inputs!$B$19,"yes","NO") | M8: =IF(AND(F8>=35,H8<=100,D8<=Inputs!$B$19,D8<=K8),"PASS","FAIL")
A9: Ballscrew 25 mm lead | B9: 25 | C9: - | D9: =ROUND(15000/B9,0) | E9: =B9*D9 | F9: =ROUND(2*3.14159*Inputs!$B$20*(Inputs!$B$18*Inputs!$B$23)*1000/B9,0) | G9: =ROUND(150*B9/(2*3.14159*Inputs!$B$20*1000),2) | H9: =ROUND(G9/Inputs!$B$18*100,0) | I9: =(Inputs!$B$4+Inputs!$B$22) | J9: =ROUND(Inputs!$B$53*Inputs!$B$54*10000000/I9^2,0) | K9: =J9/2 | L9: =IF(D9<=Inputs!$B$19,"yes","NO") | M9: =IF(AND(F9>=35,H9<=100,D9<=Inputs!$B$19,D9<=K9),"PASS","FAIL")
A10: Rack m1 z12 | B10: 1 | C10: 12 | D10: =ROUND(15000/(3.14159*B10*C10),0) | E10: =ROUND(3.14159*B10*C10*D10,0) | F10: =ROUND(Inputs!$B$21*(Inputs!$B$18*Inputs!$B$23)*1000/(B10*C10/2),0) | G10: =ROUND(150*B10*C10/2/1000,2) | H10: =ROUND(G10/Inputs!$B$18*100,0) | I10: =(Inputs!$B$4+Inputs!$B$22) | J10: - | K10: - | L10: n/a | M10: =IF(AND(F10>=35,H10<=100,D10<=Inputs!$B$19),"PASS","FAIL")
A11: Rack m1.5 z16 | B11: 1.5 | C11: 16 | D11: =ROUND(15000/(3.14159*B11*C11),0) | E11: =ROUND(3.14159*B11*C11*D11,0) | F11: =ROUND(Inputs!$B$21*(Inputs!$B$18*Inputs!$B$23)*1000/(B11*C11/2),0) | G11: =ROUND(150*B11*C11/2/1000,2) | H11: =ROUND(G11/Inputs!$B$18*100,0) | I11: =(Inputs!$B$4+Inputs!$B$22) | J11: - | K11: - | L11: n/a | M11: =IF(AND(F11>=35,H11<=100,D11<=Inputs!$B$19),"PASS","FAIL")
A12: Rack m2 z14 | B12: 2 | C12: 14 | D12: =ROUND(15000/(3.14159*B12*C12),0) | E12: =ROUND(3.14159*B12*C12*D12,0) | F12: =ROUND(Inputs!$B$21*(Inputs!$B$18*Inputs!$B$23)*1000/(B12*C12/2),0) | G12: =ROUND(150*B12*C12/2/1000,2) | H12: =ROUND(G12/Inputs!$B$18*100,0) | I12: =(Inputs!$B$4+Inputs!$B$22) | J12: - | K12: - | L12: n/a | M12: =IF(AND(F12>=35,H12<=100,D12<=Inputs!$B$19),"PASS","FAIL")
A14: Force avail uses 40% of rated torque (conservative at 200-900 rpm). 'Torque for 150 N cut' is at low rpm = full torque. The 900 rpm encoder cap is the binding constraint: it forces a lead >= ~17 mm to reach 15 m/min.
A15: Critical-speed note: bed 1700 -> screw ~2000 mm. For a 20 mm lead at 750 rpm you need screw >= ~25 mm dia (or a mid-span bearing) to stay under 50% of critical speed. Rack has no critical-speed limit.

Sheet Z-Drill
A1: Z AXIS / DRILLING CONSTRAINTS (2000 N downward feed)
A3: FEED FORCE (downward drilling)
A4: Z feed force (customer) | B4: =Inputs!$B$7 | C4: N | D4: customer
A5: Lead screw lead (self-locking) | B5: 2.5 | C5: mm | D5: trapezoid — holds position at power-off
A6: Lead screw dia | B6: 16 | C6: mm | D6: standard 16x2.5 trapezoid
A7: Lead screw efficiency | B7: 0.45 | C7: - | D7: trapezoid ~0.35-0.5
A8: DRIVE CHECK (4 Nm NEMA 24)
A9: Force a 4 Nm motor pushes thru 2.5 mm lead | B9: =ROUND(2*3.14159*Z-Drill!$B$7*Inputs!$B$18*1000/Z-Drill!$B$5,0) | C9: N | D9: F = 2.pi.eta.T / L
A10: Margin over 2000 N | B10: =Z-Drill!$B$9/Z-Drill!$B$4 | C10: x | D10: should be >= 1.5
A11: THrust BEARING (the lathe-type 'cone + cylinder')
A12: Bearing | B12: 51217 single-row thrust ball | C12: - | D12: 96 kN axial rating
A13: Axial dynamic rating C | B13: 96400 | C13: N | D13: 51217 datasheet
A14: Utilisation @ 2000 N | B14: =Z-Drill!$B$4/Z-Drill!$B$13*100 | C14: % | D14: should be a few %
A15: DRILL TORQUE (6 mm HSS in mild steel, ~1300 rpm)
A16: Drill torque (typical) | B16: 2 | C16: Nm | D16: 6 mm HSS mild steel ~1-2.5 Nm
A17: Spindle: Flipsky 7070 140KV @ 48V | B17: 2400 rpm, ~3-5 Nm cont | C17: - | D17: off-axis + belt, light moving mass
A18: Torque margin (Flipsky cont vs drill) | B18: =4/Z-Drill!$B$16 | C18: x | D18: ~3-5 Nm cont vs 2 Nm
A19: RAILS (2x HGH20 on Z carriage)
A20: Z rail static capacity (2 blocks) | B20: =2*Inputs!$B$25 | C20: N
A21: Z rail utilisation @ 2000 N | B21: =Z-Drill!$B$4/Z-Drill!$B$20*100 | C21: %

Sheet Water-Table
A1: WATER TABLE + TABLE HEIGHT LIFT (live calcs — inputs on the Inputs sheet)
A2: Water cools the kerf/workpiece (prevents warping), damps the plasma arc. Table raise/lower for access, counterweight-assisted, pin-fixed at set heights. X/Y fixed to table; plasma head keeps its own large Z travel.
A4: --- WATER LOAD ---
A5: Water volume | B5: =Inputs!B57*Inputs!B58*Inputs!B59/1000000000 | C5: m^3 | D5: L x W x depth
A6: Water mass | B6: =B5*1000 | C6: kg | D6: 1000 kg/m^3
A7: Water weight | B7: =B6*9.81 | C7: N
A8: Empty table weight | B8: =Inputs!B60*9.81 | C8: N | D8: structure mass x g
A9: FULL table weight (lifting load) | B9: =B7+B8 | C9: N | D9: what the lift system sees
A10: --- COUNTERWEIGHT + ASSIST ---
A11: Max counterweight (passive safety) | B11: =Inputs!B62*Inputs!B60*9.81 | C11: N | D11: 0.9 x EMPTY weight -> drained table can NEVER self-lift into the torch
A12: Counterweight mass | B12: =B11/9.81 | C12: kg | D12: hang on the opposite rope
A13: Residual manual force (table FULL) | B13: =(B9-B11)/Inputs!B61 | C13: N | D13: (full - CW) / MA — what the operator feels
A14: = lifting equivalent | B14: =B13/9.81 | C14: kg | D14: should feel ~<100 kg for one person
A15: Manual force (table EMPTY, lowering) | B15: =B11/Inputs!B61 | C15: N | D15: CW alone drives lowering of empty bed — keep small, controlled
A16: --- SAFETY VERDICTS ---
A17: PASS: CW < empty weight (no self-lift when drained) | B17: =IF(B11<B8,"PASS","FAIL") | D17: the 'bed crashing into workpiece if empty of water' protection — passive, no power/brake
A18: PASS: manual force (full) <= 1000 N | B18: =IF(B13<=1000,"PASS","FAIL") | D18: raise stays one-person workable; else increase MA or CW
A19: Cable working load per rope part | B19: =B9/Inputs!B61 | C19: N | D19: full weight shared over MA rope parts (CW unloads the rest)
A20: PASS: cable safety factor >= 10 | B20: =IF(Inputs!B66/B19>=10,"PASS","FAIL") | D20: breaking / working
A21: PASS: pin safety factor >= 5 | B21: =IF(Inputs!B67*2/B9>=5,"PASS","FAIL") | D21: 2 x pin shear vs full weight — pins hold every set position
A22: --- FILL / DRAIN ---
A23: Fill time | B23: =B5*1000/Inputs!B63 | C23: min | D23: volume / pump flow (basic pump)
A24: Drain | B24: gravity + sump | D24: drain hose to floor drain; optional drain pump for moving
A25: --- MECHANICAL DESIGN (notes from user 2026-10-21) ---
A26: Guides | B26: telescoping square tube: smaller tube inside main column, bearings guide it
A27: Lift | B27: pulley + steel cable + counterweight (assist, not full lift)
A28: Positioning | B28: pins fix the table at set heights; cable can slack off — no power/brake at rest
A29: Safety | B29: CW limit + mechanical detents: drained bed can only rest at pinned heights, can't self-lift
A30: Axes | B30: X/Y fixed to table — whole table raises; plasma head keeps its own LARGE Z travel
A31: OPERATING POLICY (2026-10-21)
A32: Drain BEFORE raising | B32: full table only LOWERS (CW-assisted); drained table is light and easy to raise
A33: One-off job shop | B33: not a production machine — manual fixturing per process; manual tool change for now, ATC possible later
